#VRML_SIM R2019b utf8
WorldInfo {
}
Viewpoint {
  orientation 0.5431295441299308 0.7587270375871578 0.35964368578834954 4.831318330551581
  position -1.585249294107231 2.494349177561445 0.8321973876620089
}
TexturedBackground {
}
TexturedBackgroundLight {
}
Solid {
  children [
    Shape {
      appearance PBRAppearance {
        baseColorMap ImageTexture {
          url [
            "/usr/local/webots/projects/appearances/protos/textures/chequered_parquetry/chequered_parquetry_base_color.jpg"
          ]
        }
        roughnessMap ImageTexture {
          url [
            "/usr/local/webots/projects/appearances/protos/textures/chequered_parquetry/chequered_parquetry_roughness.jpg"
          ]
        }
        metalness 0
        normalMap ImageTexture {
          url [
            "/usr/local/webots/projects/appearances/protos/textures/chequered_parquetry/chequered_parquetry_normal.jpg"
          ]
        }
        normalMapFactor 0.8
        occlusionMap ImageTexture {
          url [
            "/usr/local/webots/projects/appearances/protos/textures/chequered_parquetry/chequered_parquetry_occlusion.jpg"
          ]
        }
      }
      geometry IndexedFaceSet {
        coord Coordinate {
          point [
            -5 0 -5
            5 0 -5
            -5 0 5
            5 0 5
          ]
        }
        texCoord TextureCoordinate {
          point [
            0 0
            20 0
            0 20
            20 20
          ]
        }
        coordIndex [
          0, 2, 3, 1, -1
        ]
        texCoordIndex [
          2, 0, 1, 3, -1
        ]
      }
    }
  ]
  name "floor"
  model "floor"
  boundingObject Plane {
    size 10 10
  }
  locked TRUE
}
Robot {
  translation 0 0.075 0
  children [
    DEF GR_BODY Group {
      children [
        DEF ROBOT_BODY Shape {
          appearance PBRAppearance {
            baseColor 0.9869535362783246 0.1892576485847257 0.11616693369954986
          }
          geometry DEF G_BODY Box {
            size 0.25 0.07 0.1
          }
        }
        DEF CRAZY_WHEEL Transform {
          translation 0.11 -0.05 0
          children [
            Shape {
              appearance PBRAppearance {
                baseColor 0.05510032806897078 0 0.9981994354161898
                roughness 1
                metalness 0
              }
              geometry DEF G_CRAZYWHEEL Sphere {
                radius 0.015
              }
            }
          ]
        }
      ]
    }
    DEF WHEEL1_JOINT HingeJoint {
      jointParameters HingeJointParameters {
        axis 0 0 1
        anchor -0.05 0 0.06
      }
      device [
        PositionSensor {
          name "encoder1"
          resolution 0.00524
        }
        RotationalMotor {
          name "motor_right"
          maxVelocity 4.92
          maxTorque 4.2
        }
      ]
      endPoint DEF WHEEL1 Solid {
        translation -0.05 0 0.06
        rotation -1 0 0 1.570799693899574
        children [
          DEF SH_WHEEL Shape {
            appearance DEF C_WHEEL PBRAppearance {
              baseColor 0 0 0
              roughness 1
              metalness 0
            }
            geometry DEF G_WHEEL Cylinder {
              height 0.02
              radius 0.075
            }
          }
        ]
        boundingObject USE G_WHEEL
        physics Physics {
        }
      }
    }
    DEF WHEEL2_JOINT HingeJoint {
      jointParameters HingeJointParameters {
        axis 0 0 1
        anchor -0.05 0 -0.06
      }
      device [
        PositionSensor {
          name "encoder2"
          resolution 0.00524
        }
        RotationalMotor {
          name "motor_left"
          maxVelocity 4.92
          maxTorque 4.2
        }
      ]
      endPoint Solid {
        translation -0.05 0 -0.06
        rotation -1 0 0 1.5708003061004252
        children [
          Shape {
            appearance USE C_WHEEL
            geometry USE G_WHEEL
          }
        ]
        name "solid(1)"
        boundingObject USE G_WHEEL
        physics Physics {
        }
      }
    }
    DistanceSensor {
      translation 0.12 0 -0.05
      rotation 0 1 0 0.26180030610042526
      children [
        Solid {
          children [
            DEF DIS_BOX Shape {
              appearance PBRAppearance {
              }
              geometry Box {
                size 0.02 0.02 0.02
              }
            }
          ]
        }
      ]
      name "dis__sensor1"
      boundingObject USE DIS_BOX
      lookupTable [
        0 0 0
        0.02 0 0
        5 1659 0
      ]
    }
    DistanceSensor {
      translation 0.12 0 0.05
      rotation 0 1 0 -0.26180030610042526
      children [
        Solid {
          children [
            USE DIS_BOX
          ]
        }
      ]
      name "dis_sensor2"
      boundingObject USE DIS_BOX
      lookupTable [
        0 0 0
        0.02 0 0
        5 1659 0
      ]
    }
  ]
  boundingObject USE GR_BODY
  physics Physics {
    mass 1.5
  }
  controller "UX34_Exam_Solis_Pierre"
}
